Traceback (most recent call last):
  File "rectum_embedding_param_sweep.py", line 7, in <module>
    import pandas as pd
  File "/nfs/users/nfs_b/bh18/.local/lib/python3.7/site-packages/pandas/__init__.py", line 22, in <module>
    from pandas.compat import (
  File "/nfs/users/nfs_b/bh18/.local/lib/python3.7/site-packages/pandas/compat/__init__.py", line 15, in <module>
    from pandas.compat.numpy import (
  File "/nfs/users/nfs_b/bh18/.local/lib/python3.7/site-packages/pandas/compat/numpy/__init__.py", line 7, in <module>
    from pandas.util.version import Version
  File "/nfs/users/nfs_b/bh18/.local/lib/python3.7/site-packages/pandas/util/__init__.py", line 1, in <module>
    from pandas.util._decorators import (  # noqa
  File "/nfs/users/nfs_b/bh18/.local/lib/python3.7/site-packages/pandas/util/_decorators.py", line 14, in <module>
    from pandas._libs.properties import cache_readonly  # noqa
  File "/nfs/users/nfs_b/bh18/.local/lib/python3.7/site-packages/pandas/_libs/__init__.py", line 13, in <module>
    from pandas._libs.interval import Interval
  File "pandas/_libs/interval.pyx", line 1, in init pandas._libs.interval
ValueError: numpy.ufunc size changed, may indicate binary incompatibility. Expected 216 from C header, got 192 from PyObject
